Workbook

Sheet Итоги
C2: =NOW() -> 46137.959 | D2: 46142 | E2: Отзыв утвержден | F2: 46171 | H2: Всего студентов
B3: н/я | C3: в ИСУ нет ИЗ
C4: Черновик
B8: № п/п | C8: Ф.И.О. | D8: Группа | E8: Рук | F8: Оценка | G8: ППА | H8: Примечание
C15: ИЗ ИСУ утверждено 02.05.25 | D15: Формирование отчета 24.05.25
C16: ИЗ Черновик 24.05.25
C17: ИЗ на согласовании 24.05.25 | D17: Отзыв утвержден 21.05.25
C23: =10+17+18+19+19+21 -> 104

Sheet н
B1: =NOW() -> 46137.959
C2: группа | G2: =COUNTIF(G4:G116, ">0") -> 62
A3: № п/п | B3: Ф.И.О. | C3: Оценка | D3: Рук | E3: Руководитель ВКР
A5: 1 | B5: Борецкий Даниил Александрович | C5: 3445 | E5: Еритенко Николай Алексеевич | G5: 1
A6: =A5+1 -> 2 | B6: Жуков Владимир Александрович | C6: 3445 | E6: Есипов Дмитрий Андреевич | G6: 1
A7: =A6+1 -> 3 | B7: Золотарев Григорий Романович | C7: 3445 | E7: Левко Игорь Владимирович | G7: 1
A8: =A7+1 -> 4 | B8: Кирилин Семён Вячеславович | C8: 3445 | E8: Коржук Виктория Михайловна | G8: 1
A9: =A8+1 -> 5 | B9: Коптяев Александр Араикович | C9: 3445 | E9: Канжелев Юрий Алексеевич | G9: 1
A10: =A9+1 -> 6 | B10: Ложкин Владислав Сергеевич | C10: 3445 | E10: Ткалич Вера Леонидовна | G10: 1
A11: =A10+1 -> 7 | B11: Никуличев Владислав Андреевич | C11: 3445 | E11: Коржук Виктория Михайловна | G11: 1
A12: =A11+1 -> 8 | B12: Харченко Андрей Андреевич | C12: 3445 | E12: Савков Сергей Витальевич | G12: 1
A13: =A12+1 -> 9 | B13: Чекмезов Константин Николаевич | C13: 3445 | E13: Пшеничный Кирилл Анатольевич | G13: 1
A14: =A13+1 -> 10 | B14: Шурыгин Данил Сергеевич | C14: 3445 | E14: Федоров Иван Романович | G14: 1
A15: =A14+1 -> 11 | B15: Юдина Маргарита | C15: 3445 | E15: Коржук Виктория Михайловна | G15: 1
A16: =A15+1 -> 12 | B16: Беккер Роман Александрович | C16: 3446 | E16: Ищенко Алексей Петрович | G16: 1
A17: =A16+1 -> 13 | B17: Дырин Игорь Денисович | C17: 3446 | E17: Левко Игорь Владимирович | G17: 1
... A40: =A39+1 -> 36 | B40: Кукелко Владислав Дмитриевич | C40: 3449 | E40: Мешков Андрей Владимирович | G40: 1
A41: =A40+1 -> 37 | B41: Питерский Павел Павлович | C41: 3449 | E41: Есипов Дмитрий Андреевич | F41: ООО "НТЦ Нептунит" | G41: 1
A42: =A41+1 -> 38 | B42: Станбеков Султан Эрнисович | C42: 3449 | E42: Ханов Артур Рафаэльевич | G42: 1
A43: =A42+1 -> 39 | B43: Степанов Егор Константинович | C43: 3449 | E43: Бойко Андрей Михайлович | F43: ИТМО | G43: 1
A44: =A43+1 -> 40 | B44: Чупанов Курбанмагомед Шамильевич | C44: 3449 | E44: Коржук Виктория Михайловна | G44: 1
A45: =A44+1 -> 41 | B45: Гусь Тимофей Михаил Артемович | C45: 3450 | E45: Авдонин Иван Александрович | G45: 1
A46: =A45+1 -> 42 | B46: Ембулаев Дмитрий Юрьевич | C46: 3450 | E46: Левко Игорь Владимирович | G46: 1
A47: =A46+1 -> 43 | B47: Ефимов Матвей Дмитриевич | C47: 3450 | E47: Еритенко Николай Алексеевич | G47: 1
A48: =A47+1 -> 44 | B48: Ищенко Андрей Львович | C48: 3450 | E48: Ищенко Алексей Петрович | F48: Газинформсервис | G48: 1
A49: =A48+1 -> 45 | B49: Милютин Павел Алексеевич | C49: 3450 | E49: Есипов Дмитрий Андреевич | G49: 1
A50: =A49+1 -> 46 | B50: Чередников Лев Викторович | C50: 3450 | E50: Ханов Артур Рафаэльевич | G50: 1
A51: =A50+1 -> 47 | B51: Блинов Матвей Сергеевич | C51: 3451 | E51: Беззатеев Сергей Валентинович | G51: 1
A52: =A51+1 -> 48 | B52: Бунтов Станислав Андреевич | C52: 3451 | E52: Менщиков Александр Алексеевич | G52: 1
A53: =A52+1 -> 49 | B53: Бычков Илья Алексеевич | C53: 3451 | E53: Попов Илья Юрьевич | G53: 1
A54: =A53+1 -> 50 | B54: Верхозин Михаил Александрович | C54: 3451 | E54: Ханов Артур Рафаэльевич | G54: 1
A55: =A54+1 -> 51 | B55: Кадырова Тамилла Абдуллаевна | C55: 3451 | E55: Грозов Владимир Андреевич | G55: 1
A56: =A55+1 -> 52 | B56: Мительштет Артем Игоревич | C56: 3451 | E56: Савков Сергей Витальевич | G56: 1
A57: =A56+1 -> 53 | B57: Михайлик Антон Денисович | C57: 3451 | E57: Менщиков Александр Алексеевич | G57: 1
A58: =A57+1 -> 54 | B58: Тихомиров Данил Романович | C58: 3451 | E58: Менщиков Александр Алексеевич | G58: 1
A59: =A58+1 -> 55 | B59: Филоненко Екатерина Денисовна | C59: 3451 | E59: Михайличенко Ольга Викторовна | G59: 1
A60: =A59+1 -> 56 | B60: Цырцанов Андрей Александрович | C60: 3451 | E60: Волхонский Владимир Владимирович | F60: СПб ГКУ «СПб ИАЦ» | G60: 1
A61: =A60+1 -> 57 | B61: Киреев Ханиль Львович | C61: 3452 | E61: Савков Сергей Витальевич | G61: 1
A62: =A61+1 -> 58 | B62: Перминова Елизавета Андреевна | C62: 3452 | E62: Беляев Сергей Степанович | F62: ООО "Ленспецпроизводство" | G62: 1
A63: =A62+1 -> 59 | B63: Пищиков Степан Михайлович | C63: 3452 | E63: Попов Илья Юрьевич | G63: 1
...

Sheet Ссылка на образцы
B5: Здесь находятся образцы отчетных документов по ПТП:
B7: 2026_ Образцы отчетных документов ПТП – Google Диск
B9: https://drive.google.com/drive/folders/1FZet0yvM7lJGltmf8F8Iz6IkFcrNQzxo
B12: В Отчете руководителя ПТП обязательно выставляется Итоговая оценка.

Sheet N3445
B1: =NOW() -> 46137.959 | C1: =COUNTIF(C5:C22, ">0") -> 8 | J1: ПТП_Практика с 18.02.2026 по 29.04.2026 - всего 71 день | O1: 46137 | P1: Предзащиты ВКР
A2: 18 | B2: Список группы N3445 | H2: =COUNTIF(H4:H22, ">0") -> 0 | I2: =COUNTIF(I4:I22, ">0") -> 0 | L2: 2 | N2: =COUNTIF(N4:N22, ">0") -> 16 | O2: =COUNTIF(O4:O24, ">0") -> 4 | P2: 46137 | R2: 8 917 478 87 95 | S2: doverevkin@itmo.ru | T2: ЦК Даниил Веревкин
A3: № п/п | B3: Ф.И.О. | C3: Оценка | E3: Руководитель ВКР | F3: Место прохождения практики (юр.название ООО "Пример") | G3: Профиль компании | J3: Руководитель практики | N3: ИЗ ИСУ | O3: Отчет в ИСУ | P3: Примечание куратора | Q3: Комментарий студентов | R3: 232 02 95 | S3: danktan7@itmo.ru
J4: ФИО | K4: e-mail | L4: Место работы | M4: Должность
A5: 1 | B5: Беляков Никита Андреевич | C5: 5 | E5: Менщиков Александр Алексеевич | F5: ООО "ВК" | G5: 62.01 Разработка компьютерного программного обеспечения | J5: Зиновьев Артем Романович | K5: artem.zinovev@vk.team | L5: ООО "ВК" | M5: Руководитель команды | N5: 1 | O5: 1
A6: =A5+1 -> 2 | B6: Борецкий Даниил Александрович | E6: Еритенко Николай Алексеевич | J6: Шерягин Максим Алексеевич | K6: Sheryagin-M@gaz-is.ru | L6: ООО "ГАЗИНФОРМСЕРВИС" | M6: Инженер-аналитик | P6: 19.04_Письмо студенту | R6: 8 910 988 04 60 | S6: daniil.boretskiy@yandex.ru
A7: =A6+1 -> 3 | B7: Доан Тхи Хоай Тхыонг | C7: 5 | E7: Канжелев Юрий Алексеевич | F7: ИТМО | G7: 85.22 Образование высшее | J7: Канжелев Юрий Алексеевич | K7: kanzhelev@gmail.com | L7: ИТМО | M7: Доцент ФБИТ | N7: 1 | O7: 1
A8: =A7+1 -> 4 | B8: Дюднев Александр Владимирович | E8: Есипов Дмитрий Андреевич | F8: Акционерное общество «Селектел» | G8: 63.11 Деятельность по обработке данных, предоставление услуг по размещению информации и связанная с этим деятельность | J8: Коробов Иван | K8: korobov.i@selectel.ru | L8: Акционерное общество «Селектел» | M8: Руководитель отдела сопровождения сервисов информационной безопасности | N8: 1 | P8: 25.04_ Отчет отправлен вн. руков. на утв. | R8: 8 952 915 99 93 | S8: dudnev890@gmail.com
A9: =A8+1 -> 5 | B9: Жуков Владимир Александрович | E9: Есипов Дмитрий Андреевич | J9: Канжелев Юрий Алексеевич | K9: kanzhelev@gmail.com | L9: ИТМО | M9: Доцент ФБИТ | P9: 18.04_Введите ИЗ в ИСУ | R9: 8 929 101 94 45 | S9: zhuv03@mail.ru
A10: =A9+1 -> 6 | B10: Золотарев Григорий Романович | E10: Левко Игорь Владимирович | F10: ПАО «Территориальная генерирующая компания №1» | G10: 35.11 Производство электроэнергии | J10: Лавров Сергей Александрович | K10: Lavrov.SA@tgc1.ru | L10: ПАО «Территориальная генерирующая компания №1» | M10: Главный специалист отдела информационной безопасности | N10: 1 | R10: 8 931 988 15 50 | S10: grisha1408396@yahoo.com
A11: =A10+1 -> 7 | B11: Кирилин Семён Вячеславович | E11: Коржук Виктория Михайловна | F11: ЗАО "РОССИ" | G11: 69.09 Деятельность, связанная с использованием вычислительной техники и информационных технологий, прочая | J11: Суровцев Игорь | K11: si@rossi.ru | L11: ЗАО "РОССИ" | M11: Начальник отдела разработок | N11: 1 | R11: 8 992 645 00 93 | S11: kirilinsemen1711@gmail.com
A12: =A11+1 -> 8 | B12: Коптяев Александр Араикович | C12: 5 | E12: Канжелев Юрий Алексеевич | F12: ЗАО "Защита электронных технологий" | G12: 62.09 Деятельность, связанная с использованием вычислительной техники и информационных технологий, прочая | J12: Кармазин Маркос Маркосович | K12: markos.k@zaozet.ru | L12: ЗАО "Защита электронных технологий" | M12: Начальник испытательной лаборатории | N12: 1 | P12: 25.04_ Отчет отправлен вн. руков. на утв. | R12: 8 911 124 79 10 | S12: maversit@gmail.com
A13: =A12+1 -> 9 | B13: Логинов Константин Олегович | C13: 5 | E13: Левко Игорь Владимирович | F13: ООО "ЦЗИ "Флагман" | G13: 71.20.9 Деятельность по техническому контролю, испытаниям и анализу | J13: Логинов Максим | K13: Siistema@bk.ru | L13: ООО "ЦЗИ "Флагман" | M13: Начальник группы СИ отдела СП и СИ | N13: 1 | O13: 1 | R13: 8 924 272 77 88 | S13: luxx2007k@gmail.com
A14: =A13+1 -> 10 | B14: Ложкин Владислав Сергеевич | E14: Федоров Иван Романович | F14: ООО "Озон Технологии" | G14: 62.01 Разработка компьютерного программного обеспечения | J14: Пшеничнова Анастасия Ильинична | K14: anapshenichnova@ozon.ru | L14: ООО "Озон Технологии" | M14: Руководитель отдела образовательных проектов | N14: 1 | R14: 8 906 366 33 79 | S14: amurchik2003@inbox.ru
A15: =A14+1 -> 11 | B15: Молитвин Илья Алексеевич | E15: Левко Игорь Владимирович | F15: ООО "Сэтл Строй" | G15: 71.12.2 Деятельность заказчичка-застройщика, генерального подрядчика | J15: Никулов Константин Вадимович | K15: knikulov@yandex.ru | L15: ООО "Сэтл Строй" | M15: Руководитель отдела защиты информационных систем | N15: 1 | R15: 8 921 398 68 37 | S15: lichkingregyl@gmail.com
A16: =A15+1 -> 12 | B16: Панкова Анастасия Андреевна | C16: 5 | E16: Салихов Максим Русланович | F16: ООО "НАНО-ОЙЛ" | G16: 49.41.1 Перевозка грузов специализированными автотранспортными средствами | J16: Таран Сергей Борисович | K16: theroach@yandex.ru | L16: ООО "НАНО-ОЙЛ" | M16: Инженер-программист | N16: 1 | P16: 25.04_ Отчет отправлен вн. руков. на утв. | R16: 8 969 726 00 21 | S16: anastasiapank070@yandex.ru
A17: =A16+1 -> 13 | B17: Сивакова Анна Васильевна | C17: 5 | E17: Федоров Иван Романович | F17: ООО "ТБанк" | G17: 64.19 — Денежное посредничество прочее | J17: Гелисханов Рустам | K17: r.a.geliskhanov@tbank.ru | L17: ООО "ТБанк" | M17: Руководитель группы ИБ | N17: 1 | P17: 25.04_ Отчет отправлен вн. руков. на утв. | R17: 8 993 347 94 08 | S17: itsrealmess@mail.ru
A18: =A17+1 -> 14 | B18: Фильченко Артём Павлович | E18: Савков Сергей Витальевич | F18: ООО "Технологии нового дня" | G18: 62.01 Разработка компьютерного программного обеспечения | J18: Кузнецов Максим | K18: kma@tssolution.ru | L18: ООО "Технологии нового дня" | M18: Руководитель технической поддержки | N18: 1
A19: =A18+1 -> 15 | B19: Харченко Андрей Андреевич | C19: 5 | E19: Савков Сергей Витальевич | F19: АО "БИОКАД" | G19: 21.20.1 Производство лекарственных препаратов для медицинского применения | J19: Ляхнов Макар Валерьевич | K19: mlyakhnov@ptsecurity.com | L19: АО «Позитив Текнолоджиз» | M19: Product Owner PT EdTechLab | N19: 1 | P19: 25.04_ Отчет отправлен вн. руков. на утв. | R19: 8 981 121 39 28 | S19: soniccraft2004@gmail.com
A20: =A19+1 -> 16 | B20: Шатровский Константин Максимович | E20: Есипов Дмитрий Андреевич | F20: Акционерное общество «Селектел» | G20: 63.11 Деятельность по обработке данных, предоставление услуг по размещению информации и связанная с этим деятельность | J20: Коробов Иван | K20: korobov.i@selectel.ru | L20: Акционерное общество «Селектел» | M20: Руководитель отдела сопровождения сервисов информационной безопасности | N20: 1 | P20: 25.04_ Отчет отправлен вн. руков. на утв. | R20: 8 950 256 37 28 | S20: kshatrovskii@yandex.ru
A21: =A20+1 -> 17 | B21: Шурыгин Данил Сергеевич | C21: 5 | E21: Федоров Иван Романович | F21: ООО "ТБанк" | G21: 62.01 Разработка компьютерного программного обеспечения | J21: Тимофеев Андрей | K21: an.a.timofeev@tbank.ru | L21: ООО "ТБанк" | M21: Ведущий разработчик | N21: 1 | O21: 1 | R21: 8 919 353 11 84 | S21: dan.shell@bk.ru
A22: =A21+1 -> 18 | B22: Юдина Маргарита | E22: Левко Игорь Владимирович | F22: ФГАОУВО "Национальный исследовательский университет ИТМО" | G22: 85.22 Образование высшее | J22: Канжелев Юрий Алексеевич | K22: kanzhelev@gmail.com | L22: ИТМО | M22: Доцент ФБИТ | N22: 1
A23: 46137 | B23: Предзащиты ВКР
B38: =A2+'N3446'!A2+'N3447'!A2+'N3448'!A2+'N3449'!A2+'N3450'!A2+'N3451'!A2+'N3452'!A2 -> 144 | K38: =E41 -> 141 | L38: ИЗ | M38: Отчет
B39: =I2+'N3446'!I2+'N3447'!I2+'N3448'!I2+'N3449'!I2+'N3450'!I2+'N3451'!I2+'N3452'!I2 -> 5 | E39: =B38-B39 -> 139 | K39: =K38-L39 -> 23 | L39: =N2+'N3446'!N2+'N3447'!N2+'N3448'!N2+'N3449'!N2+'N3450'!N2+'N3451'!N2+'N3452'!N2 -> 118 | M39: =O2+'N3446'!O2+'N3447'!O2+'N3448'!O2+'N3449'!O2+'N3450'!O2+'N3451'!O2+'N3452'!O2 -> 30
B40: =H2+'N3446'!H2+'N3447'!H2+'N3448'!H2+'N3449'!H2+'N3450'!H2+'N3451'!H2+'N3452'!H2 -> 2
B41: =B39-B40 -> 3 | E41: =B38-B41 -> 141 | L41: ИТМО
L42: =L2+'N3446'!L2+'N3447'!L2+'N3448'!L2+'N3449'!L2+'N3450'!L2+'N3451'!L2+'N3452'!L2 -> 36
K45: Ф.И.О. | L45: Группа | M45: УП
J46: восстанов | K46: Чередников Лев Викторович | L46: 3450 | M46: Нет
J47: восстанов | K47: Бунтов Станислав Андреевич | L47: 3451 | M47: Нет
J48: восстанов | K48: Зворыгин Александр Сергеевич | L48: 3446 | M48: Нет
K50: 8 917 478 87 95 | L50: doverevkin@itmo.ru
L51: danktan7@itmo.ru

Sheet N3446
B1: =NOW() -> 46137.959 | C1: =COUNTIF(C5:C25, ">0") -> 4 | J1: ПТП_Практика с 18.02.2026 по 29.04.2026 - всего 71 день | O1: 46141 | P1: Предзащиты ВКР
A2: 20 | B2: Список группы N3446 | H2: =COUNTIF(H4:H25, ">0") -> 1 | I2: =COUNTIF(I4:I25, ">0") -> 1 | L2: 7 | N2: =COUNTIF(N4:N25, ">0") -> 17 | O2: =COUNTIF(O4:O25, ">0") -> 3 | P2: 46137
A3: № п/п | B3: Ф.И.О. | C3: Оценка | E3: Руководитель ВКР | F3: Место прохождения практики (юр.название ООО "Пример") | G3: Профиль компании | J3: Руководитель практики | N3: ИЗ ИСУ | O3: Отчет в ИСУ | P3: Примечание куратора | Q3: Комментарий студентов
J4: ФИО | K4: e-mail | L4: Место работы | M4: Должность
A5: 1 | B5: Беккер Роман Александрович | E5: Ищенко Алексей Петрович | F5: ООО "Яндекс.Технологии" | H5: 1 | I5: 1 | J5: 06.04..2026 | K5: 06.04..2026 | L5: ООО "Яндекс Технологии" | M5: 06.04..2026 | P5: 18.04_Введите данные вн. руководителя и ИЗ в ИСУ | R5: 8 995 570 48 41 | S5: berohomepc@gmail.com | T5: 24.03.26 Письмо студенту Восстан. 2024/25 гр. 34452 УП-4, Нет - ПТП, ДП
A6: =A5+1 -> 2 | B6: Гридин Георгий Евгеньевич | E6: Левко Игорь Владимирович | F6: АО "ЭВРИКА" | G6: 26.20 - Производство компьютеров и периферийного оборудования | J6: Веселова Дарья Юрьевна | K6: Dveselova@gmail.com | L6: АО "ЭВРИКА" | M6: Заместитель начальника отдела разработки специальных систем | N6: 1
A7: =A6+1 -> 3 | B7: Дырин Игорь Денисович | E7: Левко Игорь Владимирович | F7: ООО «КНС ГРУПП» | J7: Федяева Алёна Алексеевна | K7: a.fedyaeva@yadro.com | L7: ООО «КНС ГРУПП» | M7: Старший инженер-программист | N7: 1
A8: =A7+1 -> 4 | B8: Зворыгин Александр Сергеевич | C8: 5 | E8: Есипов Дмитрий Андреевич | J8: гр.34461_2024/25 | K8: УП - н/я | L8: ПТП - 5 | M8: ПД - 5 | O8: Восст | P8: 24.03.26 Письмо студенту | R8: 8 904 354 95 31 | S8: shura02.03.15.a@gmail.com
A9: =A8+1 -> 5 | B9: Измайлова Арина Артуровна | E9: Левко Игорь Владимирович | F9: ООО «Техцентр | G9: 63.11 Деятельность по обработке данных, предоставление услуг по размещению информации и связанная с этим деятельность | J9: Старобинец Дмитрий Юрьевич | K9: Starobinets@tc-secur.ru | L9: ООО «Техцентр» | M9: Начальник отдела проектирования СЗИ | N9: 1
A10: =A9+1 -> 6 | B10: Кузнецов Александр Геннадьевич | E10: Гирик Алексей Валерьевич | F10: ООО "Вистэк Рус" | G10: Разработка компьютерного программного обеспечения (62.01) | J10: Даутов Руслан Хурматович | K10: ruslan.dautov@vstack.com | L10: ООО "Вистэк Рус" | M10: Руководитель разработки облачной панели vStack | N10: 1 | P10: 25.04_ Письмо студ | R10: 7 965 784 61 82 | S10: alekus2004@gmail.com
A11: =A10+1 -> 7 | B11: Лопарева Милена Александровна | E11: Канжелев Юрий Алексеевич | F11: ООО "ГАЗИНФОРМСЕРВИС" | G11: создание систем обеспечения информационной и инженерной безопасности | J11: Калинина Мария Валентиновна | K11: Kalinina-M@gaz-is.ru | L11: ООО "ГАЗИНФОРМСЕРВИС" | M11: Руководитель группы испытаний значимых объектов критической информационной инфраструктуры | N11: 1 | R11: 7 963 843 29 65 | S11: lopareva04@list.ru
A12: =A11+1 -> 8 | B12: Маслов Никита Иванович | E12: Лукашов Иван Викторович | F12: ООО "ТС Солюшен" | G12: 62.03 Деятельность по управлению компьютерным оборудованием | J12: Кузнецов Максим Андреевич | K12: kma@tssolution.ru | L12: ООО "ТС Солюшен" | M12: Руководитель технической поддержки | N12: 1 | P12: 25.04_ Отчет отправлен вн. руков. на утв. | R12: 7 995 654 67 58 | S12: manick01@yandex.ru
A13: =A12+1 -> 9 | B13: Милютин Семён Олегович | E13: Попов Илья Юрьевич | F13: ФГУП "НПП"Гамма" | G13: информационная безопасность | J13: Вавилов Александр Сергеевич | K13: vavilov@spb.nppgamma.ru | L13: ФГУП "НПП"Гамма"" | M13: Начальник управления системных проектов | N13: 1
A14: =A13+1 -> 10 | B14: Михайлов Тимофей Дмитриевич | C14: 5 | E14: Грозов Владимир Андреевич | F14: ФГАОУ ВО «НИУ ИТМО» | G14: 85.22 Образование высшее | J14: Грозов Владимир Андреевич | K14: vladimirgrozov@mail.ru | L14: ИТМО | M14: Преподаватель практики, научный сотрудник ФБИТ | N14: 1 | O14: 1 | R14: 8 931 280 30 35 | S14: texxbeast@gmail.com
A15: =A14+1 -> 11 | B15: Назаренко Данила Сергеевич | E15: Канжелев Юрий Алексеевич | F15: ПАО «Совкомбанк» | G15: 64.19 — Денежное посредничество прочее | J15: Леонов Семен Сергеевич | K15: leonovss@sovcombank.ru | L15: ПАО «Совкомбанк» | M15: Начальник отдела защиты платежных сервисов | N15: 1 | R15: =8 950 951 77 05 -> #ERROR! | S15: ndanila472@gmail.com
A16: =A15+1 -> 12 | B16: Омран Хади Р. И. | E16: Левко Игорь Владимирович | F16: ИТМО | G16: 85.22 Образование высшее | J16: Канжелев Юрий Алексеевич | K16: kanzhelev@gmail.com | L16: ИТМО | M16: Доцент практики, ФБИТ | N16: 1 | P16: 22.04_Письмо студенту | R16: 7 921 335 74 40 | S16: Hadyemran06@gmail.com
A17: =A16+1 -> 13 | B17: Саранцев Владимир | E17: Есипов Дмитрий Андреевич | F17: ИТМО | G17: 85.22 Образование высшее | J17: Канжелев Юрий Алексеевич | K17: iakanzhelev@itmo.ru | L17: ИТМО | M17: Доцент практики, ФБИТ | N17: 1 | P17: 22.04_ на утв. Канжелева
A18: =A17+1 -> 14 | B18: Сыралёв Иван Алексеевич | C18: 5 | E18: Коржук Виктория Михайловна | F18: ИТМО | G18: 85.22 Образование высшее | J18: Канжелев Юрий Алексеевич | K18: iakanzhelev@itmo.ru | L18: ИТМО | M18: Доцент практики, ФБИТ | N18: 1 | O18: 1
A19: =A18+1 -> 15 | B19: Филаретов Юрий Александрович | E19: Федоров Иван Романович | F19: ООО "ДЕЙТЕРИЙ" | G19: Деятельность, связанная с использованием вычислительной техники и информационных технологий, прочая (62.09) | J19: Остоконский Антон Дмитриевич | K19: anton.ostrokonskiy@deiteriy.com | L19: ООО "ДЕЙТЕРИЙ" | M19: Руководтель исследовательской лаборатории | N19: 1 | R19: 8 950 285 29 52 | S19: filaretovur@mail.ru
A20: =A19+1 -> 16 | B20: Цзя Баоянь | E20: Беззатеев Сергей Валентинович | J20: Канжелев Юрий Алексеевич | K20: iakanzhelev@itmo.ru | L20: ИТМО | M20: Доцент практики, ФБИТ | N20: 1 | P20: 22.04_На утв. у Канжелева | R20: 8 931 213 62 11 | S20: jackgenius233@gmail.com
A21: =A20+1 -> 17 | B21: Чан Бао Линь | C21: 5 | E21: Канжелев Юрий Алексеевич | F21: ИТМО | G21: 85.22 Образование высшее | J21: Канжелев Юрий Алексеевич | K21: kanzhelev@gmail.com | L21: ИТМО | M21: Доцент практики, ФБИТ | N21: 1 | O21: 1 | R21: 8 950 018 01 28 | S21: linhbaotran2002@gmail.com
A22: =A21+1 -> 18 | B22: Чичагин Максим Сергеевич | E22: Канжелев Юрий Алексеевич | F22: ИТМО | G22: 85.22 Образование высшее | J22: Насонов Виталий Владимирович | K22: v.nasonov@sigma-it.ru | L22: ООО "СИГМА" | M22: Начальник отдела безопасной разработки | N22: 1
A23: =A22+1 -> 19 | B23: Шурчанов Иван Александрович | E23: Ханов Артур Рафаэльевич | F23: ИТМО | G23: 85.22 Образование высшее | J23: Канжелев Юрий Алексеевич | K23: kanzhelev@gmail.com | L23: ИТМО | M23: доцент, ФБИТ | N23: 1 | P23: 15.04_На утв. у Канжелева
A24: =A23+1 -> 20 | B24: Юткин Никита Михайлович | E24: Ханов Артур Рафаэльевич | J24: Белоногова Людмила Сергеевна | K24: admin@pravdinka.com | L24: ООО "Правдинка Плюс" | M24: Генеральный директор | P24: 19.04_Письмо студенту | R24: 8 982 517 88 70 | S24: nik_yuti@mail.ru
A25: 46141 | B25: Предзащиты ВКР

Sheet N3447
B1: =NOW() -> 46137.959 | C1: =COUNTIF(C5:C25, ">0") -> 9 | J1: ПТП_Практика с 18.02.2026 по 29.04.2026 - всего 71 день | O1: 46147 | P1: Предзащиты ВКР
A2: 21 | B2: Список группы N3447 | H2: =COUNTIF(H4:H24, ">0") -> 0 | I2: =COUNTIF(I4:I24, ">0") -> 0 | L2: 6 | N2: =COUNTIF(N4:N23, ">0") -> 14 | O2: =COUNTIF(O4:O25, ">0") -> 7 | P2: 46137
A3: № п/п | B3: Ф.И.О. | C3: Оценка | E3: Руководитель ВКР | F3: Место прохождения практики (юр.название ООО "Пример") | G3: Профиль компании | J3: Руководитель практики | N3: ИЗ ИСУ | O3: Отчет в ИСУ | P3: Примечание куратора | Q3: Комментарий студентов
J4: ФИО | K4: e-mail | L4: Место работы | M4: Должность
A5: 1 | B5: Абоимова Анастасия Андреевна | E5: Ткалич Вера Леонидовна | F5: ФГУП "ГосНИИПП" | G5: 72.19 - Научные исследования и разработки в области естественных и технических наук прочие | J5: Мукало Юрий Иванович | K5: 31@gosniipp.ru | L5: ФГУП "ГосНИИПП" | M5: Начальник лаборатории | P5: 19.04_Введите ИЗ в ИСУ | R5: 8 911 742 73 01 | S5: anastasia.aboimova78@gmail.com
A6: =A5+1 -> 2 | B6: Арендаренко Максим Михайлович | E6: Ханов Артур Рафаэльевич | F6: ООО "СЭМ" | G6: 43.2 Производство электромонтажных, санитарно-технических и прочих строительно-монтажных работ | J6: Зеува Ирина Александровна | K6: zueva_irina77@mail.ru | L6: ООО "СЭМ" | M6: Заместитель директора | N6: 1 | R6: 8 921 975 68 00 | S6: maxim.arendarenko@yandex.ru
A7: =A6+1 -> 3 | B7: Баринов Николай Викторович | E7: Салихов Максим Русланович | F7: ООО «Тинькофф Центр Разработки» (ООО "ТЦР") | G7: 62.01 — Разработка компьютерного программного обеспечения | J7: Рублев Александр Александрович | K7: a.a.rublev@tbank.ru | L7: ООО "ТЦР" | M7: Руководитель направления | N7: 1 | R7: 8 960 167 13 75 | S7: nik-vik-barinov@yandex.ru
A8: =A7+1 -> 4 | B8: Болдырев Евгений Андреевич | C8: 5 | E8: Ищенко Алексей Петрович | F8: ИП "Шевлякова Татьяна Андреевна" | G8: 93.29 — Деятельность по организации отдыха и развлечений | J8: Бедарев Павел Сергеевич | K8: Cuvaki.gamer@mail.ru | L8: ИП "Шевлякова Татьяна Андреевна" | M8: Руководитель отдела персонала | N8: 1 | P8: 25.04_ Отчет отправлен вн. руков. на утв. | R8: 8 999 166 15 19 | S8: evgeniy.boldyrev.2015@mail.ru
A9: =A8+1 -> 5 | B9: Георгиев Егор Сергеевич | E9: Менщиков Александр Алексеевич | F9: ООО "Яндекс.Технологии" | G9: 62.01 — Разработка компьютерного программного обеспечения | J9: Костин Максим Владимирович | K9: maksimkostin@yandex-team.ru | L9: ООО "Яндекс.Технологии" | M9: Руководитель управления | P9: 25.04_письмо вн. руков | R9: 8 921 372 70 98 | S9: egor-georgiev@mail.ru
A10: =A9+1 -> 6 | B10: Герасимов Никита Алексеевич | E10: Ханов Артур Рафаэльевич | F10: НИУ ИТМО | G10: 85.22 Образование высшее | J10: Канжелев Юрий Алексеевич | K10: Канжелев Юрий Алексеевич | L10: ИТМО | M10: Доцент практики, ФБИТ | N10: 1
A11: =A10+1 -> 7 | B11: Гусев Даниил Игоревич | E11: Менщиков Александр Алексеевич | F11: Общество с Ограниченной Ответственностью "ТЦР" | G11: 62.01 — Разработка компьютерного программного обеспечения | J11: Александров Алексей Валерьевич | K11: a.v.aleksandrov@tbank.ru | L11: ООО "ТЦР" | M11: Руководитель направления | N11: 1
A12: =A11+1 -> 8 | B12: Елисеев Леонид Андреевич | E12: Менщиков Александр Алексеевич | J12: Пшеничнова Анастасия Ильинична | K12: anapshenichnova@ozon.ru | L12: ООО "Озон Технологии" | M12: Руководитель отдела образовательных проектов | P12: 24.04_письмо студенту | R12: 8 911 423 96 65 | S12: leonid.2004eliseev@mail.ru
A13: =A12+1 -> 9 | B13: Закурин Александр Николаевич | E13: Никольский Алексей Валерьевич | F13: ООО "Ти Хантер" | G13: 74.90.9 - Деятельность в области защиты информации и обеспечения безопасности критической информационной инфраструктуры | J13: Художилов Александр Анатольевич | K13: alexander.h@tomhunter.ru | L13: ООО "Ти Хантер" | M13: Директор по информационной безопасности | N13: 1 | R13: 8 901 285 30 99 | S13: zetzns@gmail.com
A14: =A13+1 -> 10 | B14: Кабалык Андрей Федорович | C14: 5 | E14: Попов Илья Юрьевич | F14: ООО "Ти Хантер" | G14: 74.90.9 - Деятельность в области защиты информации и обеспечения безопасности критической информационной инфраструктуры | J14: Художилов Александр Анатольевич | K14: alexander.h@tomhunter.ru | L14: ООО "Ти Хантер" | M14: Директор по информационной безопасности | N14: 1 | O14: 1
A15: =A14+1 -> 11 | B15: Каримов Николай Алексеевич | C15: 5 | E15: Савков Сергей Витальевич | F15: Общество с ограниченной ответственностью «Специальный Технологический Центр» (ООО «СТЦ») | G15: 26.20.4 Производство средств защиты информации, а также информационных и телекоммуникационных систем, защищенных с использованием средств защиты информации | J15: Короткая Елена Васильевна | K15: ekorotkaia@stc-spb.ru | L15: ООО "СТЦ" | M15: Координатор учебных проектов | N15: 1 | O15: 1
A16: =A15+1 -> 12 | B16: Климов Даниил Иванович | C16: 5 | E16: Попов Илья Юрьевич | F16: Общество с ограниченной ответственностью «ИТ ИКС 5 Технологии» | G16: 62.01 — Разработка компьютерного программного обеспечения | J16: Зайцев Андрей Иванович | K16: a.zaytsev@x5.ru | L16: ООО «ИТ ИКС 5 Технологии» | M16: Начальник отдела разработки решений управления производством | N16: 1 | P16: 25.04_ Отчет отправлен вн. руков. на утв.
A17: =A16+1 -> 13 | B17: Кравчук Владислав Владимирович | E17: Коробейников Анатолий Григорьевич | F17: ООО "ПРОМТРЕЙД" | G17: 62.01 Разработка компьютерного программного обеспечения | J17: Скорняков Кирилл Александрович | K17: skornyakovka@prmtrade.com | L17: ООО "ПРОМТРЕЙД" | M17: Генеральный директор | P17: 23.04_Повторное письмо Письмо вн. руков.
A18: =A17+1 -> 14 | B18: Нгуен Кхань Ли | C18: 5 | E18: Федоров Иван Романович | F18: ИТМО | G18: 85.22 Образование высшее | J18: Канжелев Юрий Алексеевич | K18: kanzhelev@gmail.com | L18: ИТМО | M18: Доцент практики, ФБИТ | N18: 1 | O18: 1
A19: =A18+1 -> 15 | B19: Нгуен Хоанг Ву | C19: 5 | E19: Канжелев Юрий Алексеевич | F19: ИТМО | G19: 85.22 Образование высшее | J19: Канжелев Юрий Алексеевич | K19: kanzhelev@gmail.com | L19: ИТМО | M19: Доцент практики, ФБИТ | N19: 1 | O19: 1
A20: =A19+1 -> 16 | B20: Поляков Павел Романович | C20: 5 | E20: Ищенко Алексей Петрович | F20: Акционерное общество "Национальная Авиацонно-сервисная компания" (АО "НАСК") | G20: 46.14 Деятельность агентов по оптовой торговле машинами, промышленным оборудованием, судами и летательными аппаратами | J20: Балашов Сергей Иванович | K20: s.balashov@nascompany.ru | L20: АО "НАСК" | M20: Ведущий специалист отдела информационных технологий | N20: 1 | O20: 1 | R20: 8 993 998 57 49 | S20: polyakov.pr01@gmail.com
A21: =A20+1 -> 17 | B21: Ростовцев Иван Александрович | E21: Пенин Андрей | F21: ИТМО | J21: Канжелев Юрий Алексеевич | K21: kanzhelev@gmail.com | L21: ИТМО | M21: Доцент практики, ФБИТ | N21: 1 | P21: 25.04_на утв. у Канжелева Ю.А. | R21: 8 967 352 42 68 | S21: vanrosstl@gmail.com
A22: =A21+1 -> 18 | B22: Саранчук Екатерина Романовна | C22: 5 | E22: Попов Илья Юрьевич | F22: ООО "ГК СофтБаланс" | G22: 63.11 Деятельность по обработке данных, предоставление услуг по размещению информации и связанная с этим деятельность | J22: Юрьева Евгения Константиновна | K22: yureva@softbalance.ru | L22: ООО "ГК СофтБаланс" | M22: Аналитик по информационной безопасности | N22: 1 | O22: 1 | R22: 8 963 499 01 55 | S22: katya500000000@mail.ru
A23: =A22+1 -> 19 | B23: Тихонов Иван Артемович | E23: Мухамеджанов Санжар | F23: Общество с ограниченной ответственностью «ЛАНИТ - Проекты» | G23: Проектирование и внедрение ИТ‑инфраструктуры, облачных решений, информационных систем, кибербезопасности для крупных корпоративных и государственных клиентов | J23: Федорова Марина Игоревна | K23: mifedorova@lanit.ru | L23: Общество с ограниченной ответственностью «ЛАНИТ - Проекты» | M23: Заместитель директора центра ИБ | P23: 23.04_Повторное письмо Письмо вн. руков. | R23: 8 927 747 73 11 | S23: ivan_167@bk.ru
A24: =A23+1 -> 20 | B24: Уголев Матвей Александрович | E24: Левко Игорь Владимирович | F24: ИТМО | G24: 85.22 Образование высшее | J24: Левко Игорь Владимирович | K24: levko_iv@mail.ru | L24: ИТМО | M24: Доцент, ФБИТ | N24: 1 | R24: 8 917 579 11 15 | S24: ugolevmatvey@gmail.com
A25: =A24+1 -> 21 | B25: Чу Ван Доан | C25: 5 | E25: Канжелев Юрий Алексеевич | F25: ИТМО | G25: 85.22 Образование высшее | J25: Канжелев Юрий Алексеевич | K25: kanzhelev@gmail.com | L25: ИТМО | M25: Доцент практики, ФБИТ | N25: 1 | O25: 1
A26: 46147 | B26: Предзащиты ВКР

Sheet N3448
B1: =NOW() -> 46137.959 | C1: =COUNTIF(C5:C25, ">0") -> 7 | J1: ПТП_Практика с 18.02.2026 по 29.04.2026 - всего 71 день | O1: 46144 | P1: Предзащиты ВКР
A2: 17 | B2: Список группы N3448 | H2: =COUNTIF(H4:H23, ">0") -> 0 | I2: =COUNTIF(I4:I23, ">0") -> 1 | L2: 5 | N2: =COUNTIF(N4:N23, ">0") -> 13 | O2: =COUNTIF(O4:O25, ">0") -> 6 | P2: 46137
A3: № п/п | B3: Ф.И.О. | C3: Оценка | E3: Руководитель ВКР | F3: Место прохождения практики (юр.название ООО "Пример") | G3: Профиль компании | J3: Руководитель практики | N3: ИЗ ИСУ | O3: Отчет в ИСУ | P3: Примечание куратора | Q3: Комментарий студентов
J4: ФИО | K4: e-mail | L4: Место работы | M4: Должность
A5: 1 | B5: Астрашаб Игорь Александрович | E5: Канжелев Юрий Алексеевич | I5: 1 | J5: 06.04..2026 | K5: 06.04..2026 | L5: 06.04..2026 | M5: 06.04..2026 | P5: 19.04_Введите данные руковителя и ИЗ в ИСУ
A6: =A5+1 -> 2 | B6: Балобин Василий Андреевич | E6: Левко Игорь Владимирович | F6: ООО «Конфидент» | G6: 62.01 Разработка компьютерного программного обеспечения | J6: Анискин Леонид Михайлович | K6: alm@confident.ru | L6: ООО «Конфидент» | M6: Руководитель группы тестирования и внедрения | N6: 1
A7: =A6+1 -> 3 | B7: Бондарчук Фёдор Андреевич | E7: Никольский Алексей Валерьевич | F7: ИТМО | G7: 85.22 Образование высшее | J7: Никольский Алексей Валерьевич | K7: alexey.nikolskiy.student@yandex.ru | L7: ИТМО | M7: Научный сотрудник, преподаватель практики | N7: 1
A8: =A7+1 -> 4 | B8: Гамидов Абдулгамид Абдулбасирович | C8: 5 | E8: Федоров Иван Романович | F8: ООО "АТ Девелопмент" | G8: 62.01 Разработка компьютерного программного обеспечения | J8: Трофимов Анатолий Александрович | K8: atdevelopment@yandex.ru | L8: ООО "АТ Девелопмент" | M8: Генеральный директор | N8: 1 | O8: 1 | R8: 8 963 321 49 66 | S8: gamidov-24@list.ru
A9: =A8+1 -> 5 | B9: Дмитриев Богдан | C9: 5 | E9: Никольский Алексей Валерьевич | F9: ИТМО | G9: 85.22 Образование высшее | J9: Канжелев Юрий Алексеевич | K9: kanzhelev@gmail.com | L9: ИТМО | M9: доцент, ФБИТ | N9: 1 | O9: 1
A10: =A9+1 -> 6 | B10: Зинченко Владислав Александрович | C10: 5 | E10: Пшеничный Кирилл Анатольевич | F10: ООО "АТ Девелопмент" | G10: 62.01 Разработка компьютерного программного обеспечения | J10: Трофимов Анатолий Александрович | K10: atdevelopment@yandex.ru | L10: ООО "АТ Девелопмент" | M10: Генеральный директор | N10: 1 | O10: 1 | R10: 8 909 832 70 77 | S10: anteuppv@gmail.com
A11: =A10+1 -> 7 | B11: Малахов Дмитрий Александрович | E11: Федоров Иван Романович | F11: НИУ ИТМО | G11: 85.22 Образование высшее | J11: Канжелев Юрий Алексеевич | K11: kanzhelev@gmail.com | L11: ИТМО | M11: доцент, ФБИТ | N11: 1 | R11: 89217918345 | S11: dmitriy.a.malakhov@gmail.com
A12: =A11+1 -> 8 | B12: Миронова Мария Николаевна | E12: Канжелев Юрий Алексеевич | F12: ООО «НТЦ «Нептунит» | G12: 74.90.99 Деятельность в области защиты информации прочая | J12: Карлин Михаил Игоревич | K12: mk@ntcneptunit.ru | L12: ООО «НТЦ «Нептунит» | M12: Руководитель отдела по защите информации | P12: 25.04_письмо вн. руков | R12: 8 919 461 69 61 | S12: mironova5176@gmail.com
A13: =A12+1 -> 9 | B13: Новиков Никита Святославович | E13: Канжелев Юрий Алексеевич | F13: ИТМО | G13: 85.22 Образование высшее | J13: Канжелев Юрий Алексеевич | K13: kanzhelev@gmail.com | L13: ИТМО | M13: доцент, ФБИТ | N13: 1
A14: =A13+1 -> 10 | B14: Погорелый Альберт Константинович | C14: 5 | E14: Коржук Виктория Михайловна | F14: НИУ ИТМО | G14: 85.22 Образование высшее | J14: Коржук Виктория Михайловна | K14: vmkorzhuk@itmo.ru | L14: ИТМО | M14: доцент, ФБИТ | N14: 1 | O14: 1 | R14: 8 988 487 57 37 | S14: albertpogorely@hotmail.com
A15: =A14+1 -> 11 | B15: Прохоров Григорий Дмитриевич | E15: Канжелев Юрий Алексеевич | F15: ООО "Озон Технологии" | G15: 62.01 Разработка компьютерного программного обеспечения | J15: Пшеничнова Анастасия Ильинична | K15: anapshenichnova@ozon.ru | L15: ООО "Озон Технологии" | M15: Руководитель отдела образовательных проектов | N15: 1
A16: =A15+1 -> 12 | B16: Степанова Екатерина Андреевна | C16: 5 | E16: Ищенко Алексей Петрович | F16: ООО "АБИСофт" | G16: 62.01 Разработка компьютерного программного обеспечения | J16: Башаков Андрей Александрович | K16: Andrey.Bashakov@abisoft.biz | L16: ООО "АБИСофт" | M16: Начальник отдела прикладных разработок | N16: 1 | O16: 1 | R16: 8 961 709 76 67 | S16: suetin.stepan@gmail.com
A17: =A16+1 -> 13 | B17: Суетин Степан Олегович | E17: Грозов Владимир Андреевич | F17: ООО "АТ Девелопмент" | G17: 62.01 Разработка компьютерного программного обеспечения | J17: Трофимов Анатолий Александрович | K17: atdevelopment@yandex.ru | L17: ООО "АТ Девелопмент" | M17: Генеральный директор | N17: 1
A18: =A17+1 -> 14 | B18: Суров Александр Викторович | C18: 5 | E18: Никольский Алексей Валерьевич | F18: ООО "СЦ ТЕЛРОС" | G18: 62.0 Разработка компьютерного программного обеспечения, консультационные услуги в данной области и другие сопутствующие услуги | J18: Кольвах Андрей Олегович | K18: kolvah@telros.ru | L18: ООО"СЦ ТЕЛРОС" | M18: Инженер | N18: 1 | O18: 1 | R18: 8 952 281 69 36 | S18: surovalex477@gmail.com
A19: =A18+1 -> 15 | B19: Сухарева Анастасия Сергеевна | C19: 5 | E19: Канжелев Юрий Алексеевич | F19: ООО "НОЙТЭК АйТи Солюшнс" | G19: 62.01 Разработка компьютерного программного обеспечения | J19: Смольков Андрей Сергеевич | K19: andrey.smolkov@noytech.com | L19: ООО "НОЙТЭК АйТи Солюшнс" | M19: Директор ИТ-инфраструктуры и поддержки | N19: 1 | P19: 25.04_ Отчет отправлен вн. руков. на утв.
A20: =A19+1 -> 16 | B20: Хваевский Илья Игоревич | E20: Будько Михаил Юрьевич | F20: ООО "ЛАНИТ Северо-Запад" | G20: 62.09 «Деятельность, связанная с использованием вычислительной техники и информационных технологий, прочая» | J20: Сафоклов Дмитрий | K20: dmitriy.safoklov@spb.lanit.ru | L20: ООО "ЛАНИТ Северо-Запад" | M20: Руководитель отдела интеграции | P20: 25.04_Письмо вн. руков.
A21: =A20+1 -> 17 | B21: Шевченко Никита Андреевич | E21: Есипов Дмитрий Андреевич | F21: ООО "ГАЗИНФОРМСЕРВИС" | J21: Трофименко Александр Анатольевич | K21: Trofimenko-A@gaz-is.ru | L21: ООО "ГАЗИНФОРМСЕРВИС" | M21: Начальник отдела | P21: 25.04_Письмо вн. руков. | R21: 8 978 834 52 88 | S21: nikita27.200434@gmail.com
A22: 46144 | B22: Предзащиты ВКР

Sheet N3449
B1: =NOW() -> 46137.959 | C1: =COUNTIF(C5:C25, ">0") -> 5 | J1: ПТП_Практика с 18.02.2026 по 29.04.2026 - всего 71 день | O1: 46153 | P1: Предзащиты ВКР
A2: 19 | B2: Список группы N3449 | H2: =COUNTIF(H4:H24, ">0") -> 0 | I2: =COUNTIF(I4:I24, ">0") -> 0 | L2: 7 | N2: =COUNTIF(N4:N23, ">0") -> 17 | O2: =COUNTIF(O4:O25, ">0") -> 2 | P2: 46136
A3: № п/п | B3: Ф.И.О. | C3: Оценка | E3: Руководитель ВКР | F3: Место прохождения практики (юр.название ООО "Пример") | G3: Профиль компании | J3: Руководитель практики | N3: ИЗ ИСУ | O3: Отчет в ИСУ | P3: Примечание куратора | Q3: Комментарий студентов
J4: ФИО | K4: e-mail | L4: Место работы | M4: Должность
A5: 1 | B5: Актамирова Елизавета Хусейновна | E5: Федоров Иван Романович | F5: АО «Селектел» | G5: 63.11 Деятельность по обработке данных, предоставление услуг по размещению информации и связанная с этим деятельность | J5: Суханов Никита Сергеевич | K5: suhanov@selectel.ru | L5: АО "Селектел" | M5: Архитектор систем информационной безопасности | N5: 1
A6: =A5+1 -> 2 | B6: Андреев Максим Константинович | E6: Лившиц Илья Иосифович | F6: ООО "Конфидент" | G6: 62.01 Разработка компьютерного программного обеспечения | J6: Лебедев Сергей Алексеевич | K6: lebedev.sergey@confident.ru | L6: ООО "Конфидент" | M6: Руководитель группы бизнес-анализа | N6: 1
A7: =A6+1 -> 3 | B7: Архипов Михаил Владимирович | C7: 5 | E7: Савков Сергей Витальевич | F7: ООО "АБИСофт" | G7: 62.01 Разработка компьютерного программного обеспечения | J7: Башаков Андрей Александрович | K7: Andrey.Bashakov@abisoft.biz | L7: ООО "АБИСофт" | M7: Начальник отдела прикладных разработок | N7: 1 | P7: 25.04_ Отчет отправлен вн. руков. на утв.
A8: =A7+1 -> 4 | B8: Арыстанбек Диас | E8: Есипов Дмитрий Андреевич | F8: ИТМО | G8: 85.22 Образование высшее | J8: Канжелев Юрий Алексеевич | K8: kanzhelev@gmail.com | L8: ИТМО | M8: доцент, ФБИТ | N8: 1
A9: =A8+1 -> 5 | B9: Бекина Светлана Сергеевна | E9: Федоров Иван Романович | F9: ИТМО | G9: 85.22 Образование высшее | J9: Канжелев Юрий Алексеевич | K9: kanzhelev@gmail.com | L9: ИТМО | M9: доцент, ФБИТ | N9: 1 | P9: 22.04_ Отчет на утв. у руков.
A10: =A9+1 -> 6 | B10: Ганиев Александр Дамирович | C10: 5 | E10: Грозов Владимир Андреевич | F10: ООО "Яндекс.Технологии" | G10: 62.01 Разработка компьютерного программного обеспечения | J10: Демидов Владимир Александрович | K10: vovademidov@yandex-team.ru | L10: ООО "Яндекс.Технологии" | M10: руководитель группы | N10: 1 | O10: 1 | R10: 7 (904) 111-57 02 | S10: shura.ganiev@list.ru
A11: =A10+1 -> 7 | B11: Кузнецов Иван Игоревич | E11: Канжелев Юрий Алексеевич | F11: ИТМО | G11: 85.22 Образование высшее | J11: Канжелев Юрий Алексеевич | K11: kanzhelev@gmail.com | L11: ИТМО | M11: доцент, ФБИТ | N11: 1 | R11: 7 (905) 631-75-81 | S11: ivan02.12.03@gmail.com
A12: =A11+1 -> 8 | B12: Кукелко Владислав Дмитриевич | E12: Левко Игорь Владимирович | F12: АО "СПВБ" | G12: 62.01 Разработка компьютерного программного обеспечения | J12: Дуботолков Дмитрий Владиславович | K12: dubotolkovdvl@lccnco.ru | L12: АО "СПВБ" | M12: Начальник отдела информационной безопасности | P12: 23.04_Повторное письмо вн. руковод. | R12: 8 913 933 31 26 | S12: vlad0202036@gmail.com
A13: =A12+1 -> 9 | B13: Лим Алина Олеговна | E13: Федоров Иван Романович | F13: ООО "Газпром инвест" | G13: 71.12.2 Деятельность заказчика-застройщика, генерального подрядчика | J13: Конопелько Сергей Евгеньевич | K13: skonopelko@invest.gazprom.ru | L13: ООО "Газпром Инвест" | M13: Начальник отдела информационной безопасности Управления корпоративной защиты | N13: 1 | R13: 8 911 236 78 28 | S13: limaccoop@gmail.com
A14: =A13+1 -> 10 | B14: Непеина Мария Владимировна | C14: 5 | E14: Федоров Иван Романович | F14: АО «НТЦ ЕЭС» | G14: 72.19 Научные исследования и разработки в области естественных и технических наук прочие | J14: Шулик Алексей Александрович | K14: shulik-aal@so-ups.ru | L14: АО «НТЦ ЕЭС» | M14: Начальник отдела информационной безопасности | N14: 1 | P14: 25.04_ Отчет отправлен вн. руков. на утв.
A15: =A14+1 -> 11 | B15: Питерский Павел Павлович | E15: Попов Илья Юрьевич | F15: ООО "НТЦ Нептунит" | J15: Карлин Михаил Игоревич | K15: mk@ntcneptunit.ru | L15: ООО «НТЦ «Нептунит» | M15: Руководитель отдела по защите информации | P15: 23.04_Повторное письмо вн. руковод.
A16: =A15+1 -> 12 | B16: Станбеков Султан Эрнисович | E16: Ханов Артур Рафаэльевич | F16: ИТМО | G16: 85.22 Образование высшее | J16: Канжелев Юрий Алексеевич | K16: kanzhelev@gmail.com | L16: ИТМО | M16: доцент, ФБИТ | N16: 1
A17: =A16+1 -> 13 | B17: Степанов Егор Константинович | E17: Бойко Андрей Михайлович | F17: ИТМО | G17: 85.22 Образование высшее | J17: Бойко Андрей Михайлович | K17: amboiko@itmo.ru | L17: Лаборатория "Мастерская безопасности роевых технологий" | M17: Старший научный сотрудник факультета БИТ | N17: 1 | R17: 8 931 579 02 95 | S17: ekstepanov@itmo.ru
A18: =A17+1 -> 14 | B18: Фёдоров Вячеслав Алексеевич | C18: 5 | E18: Левко Игорь Владимирович | F18: ООО "Север-метрополь" | J18: Титов Алексей Владимирович | K18: It@tort.spb.ru | L18: ООО "Север-метрополь" | M18: Начальник отдела информационных технологий | N18: 1 | P18: 25.04_ Отчет отправлен вн. руков. на утв.
A19: =A18+1 -> 15 | B19: Фирсенков Леонид Андреевич | E19: Беззатеев Сергей Валентинович | F19: ООО "Конфидент" | G19: 62.01 Разработка компьютерного программного обеспечения | J19: Анискин Леонид Михайлович | K19: alm@confident.ru | L19: ООО «Конфидент» | M19: Руководитель группы тестирования и внедрения | N19: 1 | P19: 25.04_ Отчет отправлен вн. руков. на утв. | R19: 8 921 899 69 29 | S19: leonid0907@gmail.com
A20: =A19+1 -> 16 | B20: Хачатрян Рубен Арташесович | E20: Югансон Андрей Николаевич | F20: ИТМО | J20: Югансон Андрей Николаевич | K20: a_yougunson@itmo.ru | L20: 23.04_Письмо студенту | M20: Заведующий лабораторией | N20: 1 | R20: 8 981 906 65 75 | S20: ruben-khachatryan-03@mail.ru
A21: =A20+1 -> 17 | B21: Хребтов Матвей Александрович | C21: 5 | E21: Мешков Андрей Владимирович | F21: ООО НПО «Компонент» | G21: 46.52 Торговля оптовая электронным и телекоммуникационным оборудованием и его запасными частями | J21: Туртанов Алексей Сергеевич | K21: info@npocomponent.ru | L21: ООО НПО «Компонент» | M21: Генеральный директор ООО НПО «Компонент» | N21: 1 | O21: 1
A22: =A21+1 -> 18 | B22: Чупанов Курбанмагомед Шамильевич | E22: Коржук Виктория Михайловна | F22: ИТМО | G22: 85.22 Образование высшее | J22: Канжелев Юрий Алексеевич | K22: kanzhelev@gmail.com | L22: ИТМО | M22: доцент, ФБИТ | N22: 1
A23: =A22+1 -> 19 | B23: Шабаев Алексей Геннадьевич | E23: Ханов Артур Рафаэльевич | F23: ООО "Синтез-АТ" | G23: 62.01 Разработка компьютерного программного обеспечения | J23: Скороходов Александр Дмитриевич | K23: skara1232@gmail.com | L23: ООО "Синтез-АТ" | M23: Ведущий инженер-разработчик | N23: 1 | R23: 8 981 918 54 51 | S23: lakencrin@gmail.com
A24: 46153 | B24: Предзащиты ВКР

Sheet N3450
B1: =NOW() -> 46137.959 | C1: =COUNTIF(C5:C26, ">0") -> 3 | J1: ПТП_Практика с 18.02.2026 по 29.04.2026 - всего 71 день | O1: 46148 | P1: Предзащиты ВКР
A2: 19 | B2: Список группы N3450 | H2: =COUNTIF(H4:H25, ">0") -> 0 | I2: =COUNTIF(I4:I25, ">0") -> 1 | L2: 3 | N2: =COUNTIF(N4:N25, ">0") -> 17 | O2: =COUNTIF(O4:O26, ">0") -> 1 | P2: 46137
A3: № п/п | B3: Ф.И.О. | C3: Оценка | E3: Руководитель ВКР | F3: Место прохождения практики (юр.название ООО "Пример") | G3: Профиль компании | J3: Руководитель практики | N3: ИЗ ИСУ | O3: Отчет в ИСУ | P3: Примечание куратора | Q3: Комментарий студентов
J4: ФИО | K4: e-mail | L4: Место работы | M4: Должность
A5: 1 | B5: Адамов Михаил Ильич | E5: Грозов Владимир Андреевич | F5: АО «Позитив Текнолоджиз» | G5: 62.01 Разработка компьютерного программного обеспечения | J5: Ляхнов Макар Валерьевич | K5: mlyakhnov@ptsecurity.com | L5: АО «Позитив Текнолоджиз» | M5: Product Owner PT EdTechLab | N5: 1
A6: =A5+1 -> 2 | B6: Ахраров Али Рустамович | E6: Попов Илья Юрьевич | F6: ИТМО | G6: 85.22 Образование высшее | J6: Канжелев Юрий Алексеевич | K6: kanzhelev@gmail.com | L6: ИТМО | M6: доцент, ФБИТ | N6: 1 | P6: на утв. у Канжелева Ю.А. | R6: 8 966 923 69 86 | S6: aa972139@gmail.com
A7: =A6+1 -> 3 | B7: Гусь Тимофей Михаил Артемович | E7: Авдонин Иван Александрович | F7: ООО "Мобил-груп" | J7: Замковой Дмитрий Сергеевич | K7: ds.zamkovoy@yandex.ru | L7: ООО "Мобил-груп" | M7: Директор | N7: 1 | R7: 8 981 806 80 38 | S7: tima-gus@mail.ru
A8: =A7+1 -> 4 | B8: Диденко Дмитрий Эдуардович | C8: 5 | E8: Канжелев Юрий Алексеевич | F8: АО «Селектел» | G8: 63.11 Деятельность по обработке данных, предоставление услуг по размещению информации и связанная с этим деятельность | J8: Суханов Никита Сергеевич | K8: itsec@selectel.ru | L8: АО «Селектел» | M8: Архитектор систем информационной безопасности | N8: 1 | O8: 1 | R8: 8 966 935 20 04 | S8: dimon.did.2014@gmail.com
A9: =A8+1 -> 5 | B9: Ембулаев Дмитрий Юрьевич | E9: Левко Игорь Владимирович | F9: ООО "МАС-Внештранс" | G9: 62.01 Разработка компьютерного программного обеспечения | J9: Массальский Андрей Эдуардович | K9: mas@masvt.net | L9: ООО "МАС-Внештранс" | M9: Директор | N9: 1
A10: =A9+1 -> 6 | B10: Ефимов Матвей Дмитриевич | E10: Еритенко Николай Алексеевич | F10: СПб ГУП «АТС Смольного» | G10: 61.10.9 Деятельность в области связи на базе проводных технологий | J10: Марыкин Евгений Игоревич | K10: E.marykin@sats.spb.ru | L10: СПб ГУП «АТС Смольного» | M10: Инженер по технической защите информации | N10: 1 | R10: 8 921 849 22 16 | S10: mat.efimov@gmail.com
A11: =A10+1 -> 7 | B11: Ефремов Далир Игоревич | T11: Восстан. 2024/25 гр. 34511 Нет - УП, ПТП, ДП
A12: =A11+1 -> 8 | B12: Ищенко Андрей Львович | E12: Ищенко Алексей Петрович | F12: ООО "ГАЗИНФОРМСЕРВИС" | J12: Трофименко Александр Анатольевич | K12: Trofimenko-A@gaz-is.ru | L12: ООО "ГАЗИНФОРМСЕРВИС" | M12: Начальник отдела | N12: 1
A13: =A12+1 -> 9 | B13: Клеопатров Илья Дмитриевич | E13: Югансон Андрей Николаевич | F13: ООО «Ангара Технолоджиз Груп» | G13: 62.09 Деятельность, связанная с использованием вычислительной техники и информационных технологий, прочая | J13: Поляков Илья Георгиевич | K13: i.polyakov@angarasecurity.ru | L13: ООО «Ангара Технолоджиз Груп» | M13: Руководитель отдела анализа кода | N13: 1 | R13: 8 921 888 33 88 | S13: kleostudy@gmail.com
A14: =A13+1 -> 10 | B14: Клочков Данила Александрович | C14: 5 | E14: Салихов Максим Русланович | F14: ПАО "Сбербанк" | G14: 64.19 Денежное посредничество прочее | J14: Деранков Ярослав Игоревич | K14: derankov.y.i@sberbank.ru | L14: ПАО "Сбербанк" | M14: Начальник центра компетенций по защите периметра сети | N14: 1 | P14: 25.04_ Отчет отправлен вн. руков. на утв.
A15: =A14+1 -> 11 | B15: Коротыкина Анастасия Александровна | E15: Ищенко Алексей Петрович | F15: ООО "Ядро Центр Программных Разработок" | G15: 62.01 Разработка компьютерного программного обеспечения | J15: Назаров Руслан Сергеевич | K15: r.nazarov@yadro.com | L15: ООО "Ядро Центр Программных Разработок" | M15: Директор по разработке | N15: 1
A16: =A15+1 -> 12 | B16: Купцов Даниил Геннадьевич | E16: Савков Сергей Витальевич | F16: ООО "Бастион" | G16: 74.90.9 Деятельность в области защиты информации и обеспечения безопасности критической информационной инфраструктуры | J16: Ксендзовская Яна Владимировна | K16: ya.ksendzovskaya@bastion-tech.ru | L16: ООО "Бастион" | M16: Руководитель направления образовательных программ | N16: 1
A17: =A16+1 -> 13 | B17: Лучинин Кирилл Андреевич | E17: Савков Сергей Витальевич | F17: АО "Инфосистемы Джет" | G17: 62.02 Деятельность консультативная и работы в области компьютерных технологий | J17: Серов Андрей Иванович | K17: ai.serov@jet.su | L17: АО "Инфосистемы Джет" | M17: Руководитель группы защиты приложений | N17: 1
A18: =A17+1 -> 14 | B18: Милютин Павел Алексеевич | E18: Есипов Дмитрий Андреевич | F18: ИТМО | G18: 85.22 Образование высшее | J18: Ханов Артур Рафаэльевич | K18: arhanov@itmo.ru | L18: ИТМО | M18: преподаватель ФБИТ | N18: 1
A19: =A18+1 -> 15 | B19: Новиков Владислав Дмитриевич | E19: Савков Сергей Витальевич | F19: ООО "Кибер Сервис" | G19: 62.02 Деятельность консультативная и работы в области компьютерных технологий | J19: Чербов Глеб Сергеевич | K19: g.cherbov@dsec.ru | L19: ООО "Кибер Сервис" | M19: Технический директор | N19: 1
A20: =A19+1 -> 16 | B20: Салахова Ралина Жамиловна | E20: Еритенко Николай Алексеевич | F20: ООО «Техцентр | G20: 63.11 Деятельность по обработке данных, предоставление услуг по размещению информации и связанная с этим деятельность | J20: Старобинец Дмитрий Юрьевич | K20: Starobinets@tc-secur.ru | L20: ООО «Техцентр | M20: Начальник отдела проектирования СЗИ | N20: 1
A21: =A20+1 -> 17 | B21: Чередников Лев Викторович | E21: Ханов Артур Рафаэльевич | I21: 1 | J21: Ханов Артур Рафаэльевич | K21: arhanov@itmo.ru | L21: ИТМО | M21: преподаватель ФБИТ | P21: 19.04_Срочно сообщите данные руков. ПТП и введите ИЗ в ИСУ | R21: 8 999 947 87 49 | S21: cherednikov.lev@yandex.ru нет такой почты
A22: =A21+1 -> 18 | B22: Шушпанова Екатерина | E22: Ханов Артур Рафаэльевич | F22: ИТМО | G22: 85.22 Образование высшее | J22: Канжелев Юрий Алексеевич | K22: kanzhelev@gmail.com | L22: ИТМО | M22: доцент, ФБИТ | N22: 1
A23: =A22+1 -> 19 | B23: Щерба Анна Андреевна | C23: 5 | E23: Роговой Виталий | F23: ООО "УК Благо" | G23: 70.10 Деятельность головных офисов | J23: Волков Анатолий Михайлович | K23: volkov.a@gcblago.ru | L23: ООО "УК"Благо" | M23: Начальник отдела ИТ инфраструктуры | N23: 1 | P23: 25.04_ Отчет отправлен вн. руков. на утв.
A24: 46148 | B24: Предзащиты ВКР

Sheet N3451
B1: =NOW() -> 46137.959 | C1: =COUNTIF(C5:C25, ">0") -> 8 | J1: ПТП_Практика с 18.02.2026 по 29.04.2026 - всего 71 день | O1: 46152 | P1: Предзащиты ВКР
A2: 19 | B2: Список группы N3451 | H2: =COUNTIF(H4:H23, ">0") -> 0 | I2: =COUNTIF(I4:I23, ">0") -> 1 | L2: 4 | N2: =COUNTIF(N4:N22, ">0") -> 17 | O2: =COUNTIF(O4:O24, ">0") -> 6 | P2: 46137
A3: № п/п | B3: Ф.И.О. | C3: Оценка | E3: Руководитель ВКР | F3: Место прохождения практики (юр.название ООО "Пример") | G3: Профиль компании | J3: Руководитель практики | N3: ИЗ ИСУ | O3: Отчет в ИСУ | P3: Примечание куратора | Q3: Комментарий студентов
J4: ФИО | K4: e-mail | L4: Место работы | M4: Должность
A5: 1 | B5: Блинов Матвей Сергеевич | E5: Беззатеев Сергей Валентинович | J5: Мишкин Кирилл Васильевич | K5: info@migra.ru | L5: ООО "Мигра Софт" | M5: Генеральный директор | N5: 1 | P5: 25.04_ Отчет отправлен вн. руков. на утв. | R5: 8 981 790 64 57 | S5: matvey20031@gmail.com
A6: =A5+1 -> 2 | B6: Бунтов Станислав Андреевич | E6: Ханов Артур Рафаэльевич | I6: 1 | J6: 06.04..2026 | K6: 06.04..2026 | L6: 06.04..2026 | M6: 06.04..2026 | P6: 13.04_Введите данные о руков. практики и ИЗ в ИСУ | R6: 8 921 646 25 28 | S6: buntovrip@gmail.com | T6: гр.34491_2024/25; Нет УП, ПТП , ДП
A7: =A6+1 -> 3 | B7: Бычков Илья Алексеевич | E7: Попов Илья Юрьевич | F7: ООО «ПСС» | G7: 46.51.2 Торговля оптовая программным обеспечением | J7: Сергей Павлович Казанцев | K7: skazantsev@pssbim.ru | L7: ООО "ПСС" | M7: Технический директор | N7: 1
A8: =A7+1 -> 4 | B8: Верхозин Михаил Александрович | E8: Ханов Артур Рафаэльевич | F8: ООО "Конфидент" | G8: Разработка компьютерного программного обеспечения (62.01) | J8: Лебедев Сергей Алексеевич | K8: lebedev.sergey@confident.ru | L8: ООО "Конфидент" | M8: Руководитель группы бизнес-анализа | N8: 1
A9: =A8+1 -> 5 | B9: Добрецков Дмитрий Александрович | C9: 5 | E9: Менщиков Александр Алексеевич | F9: ООО "Единое Видео" | G9: Разработка компьютерного программного обеспечения (62.01) | J9: Муханов Павел Владимирович | K9: p.mukhanov@corp.mail.ru | L9: ООО "Единое Видео" | M9: Руководитель лаборатории качества единой видеоплатформы VK | N9: 1 | O9: 1
A10: =A9+1 -> 6 | B10: Залесов Дмитрий | C10: 5 | E10: Попов Илья Юрьевич | F10: ИТМО | G10: 85.22 Образование высшее | J10: Канжелев Юрий Алексеевич | K10: kanzhelev@gmail.com | L10: ИТМО | M10: доцент, ФБИТ | N10: 1 | O10: 1
A11: =A10+1 -> 7 | B11: Зыкин Кирилл Андреевич | C11: 5 | E11: Попов Илья Юрьевич | F11: ООО "Т2 Мобайл" | G11: Деятельность в области связи на базе беспроводных технологий (61.20) | J11: Воробьева Валерия Викторовна | K11: vorval01@yandex.ru | L11: ООО "Т2 Мобайл" | M11: Старший специалист по обеспечению качества | N11: 1 | P11: 24.04_Отправлен Отчет вн. руков.
A12: =A11+1 -> 8 | B12: Кадырова Тамилла Абдуллаевна | E12: Грозов Владимир Андреевич | F12: ИТМО | G12: 85.22 Образование высшее | J12: Канжелев Юрий Алексеевич | K12: kanzhelev@gmail.com | L12: ИТМО | M12: доцент, ФБИТ | N12: 1
A13: =A12+1 -> 9 | B13: Лемешев Ярослав Андреевич | C13: 5 | E13: Попов Илья Юрьевич | F13: ООО "АйДи Инжиниринг" | G13: 63.11.1 Деятельность по созданию и использованию баз данных и информационных ресурсов | J13: Новиков Александр Михайлович | K13: novikovam@areal.ru | L13: МКАО "Ареал", ООО "АйДи Инжиниринг" - дочерняя компания | M13: Заместитель руководителя ИБ | N13: 1 | P13: 25.04_ Отчет отправлен вн. руков. на утв. | Q13: Отравил повторно | R13: 8 921 975 17 12 | S13: yaroslem@yandex.ru
A14: =A13+1 -> 10 | B14: Мительштет Артем Игоревич | E14: Савков Сергей Витальевич | F14: АО Санкт-Петербургская Валютная Биржа | G14: 66.11.1 Деятельность по организации торговли на финансовых рынках | J14: Березуцкий Алексей Леонидович | K14: berezutskiyal@spvb.ru | L14: АО Санкт -Петербургская Валютная Биржа | M14: Руководитель отдела ИБ | N14: 1
A15: =A14+1 -> 11 | B15: Михайлик Антон Денисович | C15: 5 | E15: Менщиков Александр Алексеевич | F15: ООО Платформа домиленд, город Санкт-Петербург, Свердловская рабережная 44с1 | G15: 62.01 - Разработка компьютерного программного обеспечения | J15: Трухачёв Илья Дмитриевич | K15: 0000@2853.org | L15: ООО Платформа домиленд | M15: Руководитель группы обеспечения технической надежности системы Проптеха | N15: 1 | O15: 1 | R15: 8 931 000 51 59 | S15: a.d.mihailik@yandex.ru
A16: =A15+1 -> 12 | B16: Охунов Абдулатиф Мукимович | C16: 5 | E16: Попов Илья Юрьевич | F16: ИТМО | G16: 85.22 Образование высшее | J16: Канжелев Юрий Алексеевич | K16: kanzhelev@gmail.com | L16: ИТМО | M16: доцент, ФБИТ | N16: 1 | O16: 1
A17: =A16+1 -> 13 | B17: Потылицына Кристина Алексеевна | E17: Попов Илья Юрьевич | F17: ООО «НТЦ «Нептунит» | G17: 74.90.99 Деятельность в области защиты информации прочая | J17: Карлин Михаил Игоревич | K17: mk@ntcneptunit.ru | L17: ООО «НТЦ «Нептунит» | M17: Руководитель отдела по защите информации | N17: 1
A18: =A17+1 -> 14 | B18: Саломатин Денис Николаевич | C18: 5 | E18: Коржук Виктория Михайловна | F18: ИТМО | G18: 85.22 Образование высшее | J18: Канжелев Юрий Алексеевич | K18: kanzhelev@gmail.com | L18: ИТМО | M18: доцент, ФБИТ | N18: 1 | O18: 1
A19: =A18+1 -> 15 | B19: Тихомиров Данил Романович | E19: Менщиков Александр Алексеевич | F19: ООО «МЕГАПОЛИС» | G19: 46.62 Торговля оптовая станками | J19: Алюнин Павел Владимирович | K19: megapolis.nw@mail.ru | L19: ООО «МЕГАПОЛИС» | M19: Генеральный директор | N19: 1
A20: =A19+1 -> 16 | B20: Хоменко Андрей Владимирович | E20: Попов Илья Юрьевич | F20: ООО "Конфидент" | G20: Разработка компьютерного программного обеспечения (62.01) | J20: Лебедев Сергей Алексеевич | K20: lebedev.sergey@confident.ru | L20: ООО "Конфидент" | M20: Руководитель группы бизнес-анализа | N20: 1 | P20: 25.04_ в архиве только Отчет. В Отчете нет Списка литературы. Исправьте и заново загрузите в архив
A21: =A20+1 -> 17 | B21: Цырцанов Андрей Александрович | E21: Волхонский Владимир Владимирович | F21: СПб ГКУ «СПб ИАЦ» | G21: 63.11.1 Деятельность по созданию и использованию баз данных и информационных ресурсов | J21: Трифонов Роман Алексеевич | K21: trifonov@iac.spb.ru | L21: СПб ГКУ «СПб ИАЦ» | M21: Начальник отдела обнаружения и регистрации компьютерных инцидентов | N21: 1
A22: =A21+1 -> 18 | B22: Шарапов Алексей Викторович | C22: 5 | E22: Левко Игорь Владимирович | F22: ООО «Техцентр» | G22: 63.11 Деятельность по обработке данных, предоставление услуг по размещению информации и связанная с этим деятельность | J22: Старобинец Дмитрий Юрьевич | K22: Starobinets@tc-secur.ru | L22: ООО «Техцентр» | M22: Начальник отдела проектирования СЗИ | N22: 1 | O22: 1
A23: =A22+1 -> 19 | B23: Ясаков Максим Андреевич | E23: Менщиков Александр Алексеевич | J23: гр.34511_2024/25 | K23: УП - 5 | L23: ПТП - 5 | M23: ПД - 5 | P23: Восстановление
A24: 46152 | B24: Предзащиты ВКР

Sheet N3452
B1: =NOW() -> 46137.959 | C1: =COUNTIF(C5:C25, ">0") -> 1 | J1: ПТП_Практика с 18.02.2026 по 29.04.2026 - всего 71 день | O1: 46158 | P1: Предзащиты ВКР
A2: 11 | B2: Список группы N3452 | H2: =COUNTIF(H4:H15, ">0") -> 1 | I2: =COUNTIF(I4:I15, ">0") -> 1 | L2: 2 | N2: =COUNTIF(N4:N22, ">0") -> 7 | O2: =COUNTIF(O4:O24, ">0") -> 1 | P2: 46137
A3: № п/п | B3: Ф.И.О. | C3: Оценка | E3: Руководитель ВКР | F3: Место прохождения практики (юр.название ООО "Пример") | G3: Профиль компании | J3: Руководитель практики | N3: ИЗ ИСУ | O3: Отчет в ИСУ | P3: Примечание куратора | Q3: Комментарий студентов
J4: ФИО | K4: e-mail | L4: Место работы | M4: Должность
A5: 1 | B5: Гоголева Анастасия Алексеевна | E5: Мешков Андрей Владимирович | F5: ООО "Тумларе" | J5: Энгель Камила | K5: kamila.engel@kuonitumlare.com | L5: ООО "Тумларе" | M5: Заместитель начальника отдела | P5: 19.04_Введите ИЗ в ИСУ
A6: =A5+1 -> 2 | B6: Доронин Алексей Анатольевич | C6: 5 | E6: Беляев Сергей Степанович | F6: ООО "ПСК "Северо-Запад" | G6: 41.20 Строительство жилых и нежилых зданий | J6: Куницына Екатерина Александровна | K6: hr@psksz.ru | L6: ООО "ПСК "Северо-Запад" | M6: Руководитель отдела персонала | N6: 1 | O6: 1
A7: =A6+1 -> 3 | B7: Киреев Ханиль Львович | E7: Савков Сергей Витальевич | F7: ИТМО | G7: 85.22 Образование высшее | J7: Савков Сергей Витальевич | K7: savkov@itmo.ru | L7: ИТМО | M7: Доцент практики, ФБИТ | N7: 1 | R7: 8 977 167 60 16 | S7: kireev.khanil.bs@gmail.com
A8: =A7+1 -> 4 | B8: Перминова Елизавета Андреевна | E8: Беляев Сергей Степанович | F8: ООО "Ленспецпроизводство" | G8: 26.51.6 Производство прочих приборов, датчиков, аппаратуры и инструментов для измерения, контроля и испытаний | J8: Антон Андреевич Волошин | K8: vaa@pps.ru | L8: ООО "Ленспецпроизводство" | M8: Главный инженер | N8: 1 | R8: 8 952 359 80 20 | S8: biom09@yandex.ru
A9: =A8+1 -> 5 | B9: Пищиков Степан Михайлович | E9: Попов Илья Юрьевич | F9: ООО "Гиар Геймз" | G9: 62.0: Разработка компьютерного программного обеспечения, консультационные услуги в данной области и другие сопутствующие услуги | J9: Романюта Ксения Евгеньевна | K9: kromanyuta@gear-games.com | L9: ООО "Гиар Геймз" | M9: Руководитель службы персонала | P9: 19.04_Введите ИЗ в ИСУ
A10: =A9+1 -> 6 | B10: Рядовой Тимофей Сергеевич | E10: Бучаев Абдулхамид Яхьяевич | F10: ПАО "Совкомбанк" | H10: 1 | I10: 1 | J10: Кадников Александр Андреевич | K10: 06.04..2026 | L10: ПАО "Совкомбанк" | M10: Начальник управления риск-моделирования и автоматизации | P10: 18.04_Введите данные вн. руковителя и ИЗ в ИСУ | R10: 8 999 035 03 29 | S10: timaryadovou@yandex.ru
A11: =A10+1 -> 7 | B11: Сапрыга Пётр Андреевич | E11: Гришенцев Алексей Юрьевич | F11: ФГУП "НПП"Гамма"" | G11: 72.19 - Научные исследования и разработки в области естественных и технических наук прочие | J11: Вавилов Александр Сергеевич | K11: vavilov@spb.nppgamma.ru | L11: ФГУП "НПП"Гамма"" | M11: Начальник управления системных проектов | N11: 1
A12: =A11+1 -> 8 | B12: Тушкевич Иван Вячеславович | E12: Ханов Артур Рафаэльевич | F12: ООО «Доктор Веб» | G12: 62.01 - Разработка компьютерного программного обеспечения | J12: Здобнов Игорь Геннадьевич | K12: I.Zdobnov@drweb.com | L12: ООО «Доктор Веб» | M12: Руководитель отдела антивирусных разработок и исследований | N12: 1
A13: =A12+1 -> 9 | B13: Эльгандур Йахиа Ашраф Ахмед Ахмед | E13: Будько Михаил Юрьевич | F13: ИТМО | G13: 85.22 Образование высшее | J13: Канжелев Юрий Алексеевич | K13: kanzhelev@gmail.com | L13: ИТМО | M13: Доцент ФБИТ | N13: 1
A14: =A13+1 -> 10 | B14: Юнусова Айсылу Азатовна | E14: Салихов Максим Русланович | F14: АО "Альфа-банк" | G14: 62.09 Деятельность, связанная с использованием вычислительной техники и информационных технологий, прочая | J14: Белоус Полина Артуровна | K14: belous.p.a@gmail.com | L14: АО "Альфа-банк" | M14: Начальник отдела развития аналитической отчетности | N14: 1
A15: =A14+1 -> 11 | B15: Нкунку Битсинду Дьё Бени Пьер Круаянс | E15: Савков Сергей Витальевич | J15: гр.34531_2024/25 | K15: УП - 5 | L15: ПТП - 5 | M15: ПД - 4с | P15: Восстановление
A16: 46158 | B16: Предзащиты ВКР
